<?xml version="1.0"?>
<robot name="my_robot" xmlns:xacro="http://www.ros.org/wiki/xacro">

  <!-- Define constants -->
  <xacro:property name="PI" value="3.14159" />
  <xacro:property name="wheel_mass" value="5.0" />
  <xacro:property name="wheel_radius" value="0.1" />
  <xacro:property name="wheel_length" value="0.05" />

  <!-- Include Gazebo plugins -->
  <xacro:include filename="$(find my_robot)/urdf/my_robot.gazebo.xacro" />
  
  <!-- Links -->
  <link name="robot_footprint"></link>

  <!-- chassis -->
  <link name='chassis'>
    <inertial>
      <mass value="15.0" />
      <origin xyz="0 0 0" rpy="0 0 0" />
      <inertia ixx="0.1" ixy="0.0" ixz="0.0" iyy="0.1" iyz="0.0" izz="0.1" />
    </inertial>
    <collision name='chassis_collision'>
      <origin xyz="0 0 0" rpy="0 0 0" /> 
      <geometry>
        <box size="0.4 0.2 0.1" />
      </geometry>
    </collision>
    <visual name='chassis_visual'>
      <origin xyz="0 0 0" rpy="0 0 0" />
      <geometry>
        <box size="0.4 0.2 0.1" />
      </geometry>
      <material name="blue">
        <color rgba="0.0 0.0 1.0 1.0"/>
      </material>
    </visual>

    <collision name='back_caster_collision'>
      <origin xyz="-0.15 0 -0.05" rpy="0 0 0" />
      <geometry> 
        <sphere radius="0.0499" />
      </geometry>
    </collision>
    <visual name='back_caster_visual'>
      <origin xyz="-0.15 0 -0.05" rpy="0 0 0" />
      <geometry>
        <sphere radius="0.05" />
      </geometry>
      <material name="grey">
        <color rgba="0.5 0.5 0.5 1.0"/>
      </material>
    </visual>
    <collision name='front_caster_collision'>
      <origin xyz="0.15 0 -0.05" rpy="0 0 0" />
      <geometry>
        <sphere radius="0.0499" />
      </geometry>
    </collision>
    <visual name='front_caster_visual'>
      <origin xyz="0.15 0 -0.05" rpy="0 0 0" />
      <geometry>
        <sphere radius="0.05" />
      </geometry>
      <material name="grey">
        <color rgba="0.5 0.5 0.5 1.0"/>
      </material>
    </visual>
  </link>

  <!-- right_wheel -->
  <link name='right_wheel'>
    <inertial>
      <mass value="${wheel_mass}" />
      <origin xyz="0 0 0" rpy="1.5707 0 0" />
      <inertia ixx="0.1" ixy="0.0" ixz="0.0" iyy="0.1" iyz="0.0" izz="0.1" />
    </inertial>
    <collision name='right_wheel_collision'>
      <origin xyz="0 0 0" rpy="1.5707 0 0" /> 
      <geometry>
        <cylinder radius="${wheel_radius}" length='${wheel_length}' />
      </geometry>
    </collision>
    <visual name='right_wheel_visual'>
      <origin xyz="0 0 0" rpy="1.5707 0 0" />
      <geometry>
        <cylinder radius="${wheel_radius}" length='${wheel_length}' />
      </geometry>
      <material name="green">
        <color rgba="0.0 0.1 0 1.0"/>
      </material>
    </visual>
  </link>

  <!-- left_wheel -->
  <link name='left_wheel'>
    <inertial>
      <mass value="${wheel_mass}" />
      <origin xyz="0 0 0" rpy="1.5707 0 0" />
      <inertia ixx="0.1" ixy="0.0" ixz="0.0" iyy="0.1" iyz="0.0" izz="0.1" />
    </inertial>
    <collision name='left_wheel_collision'>
      <origin xyz="0 0 0" rpy="1.5707 0 0" /> 
      <geometry>
        <cylinder radius="${wheel_radius}" length='${wheel_length}' />
      </geometry>
    </collision>
    <visual name='left_wheel_visual'>
      <origin xyz="0 0 0" rpy="1.5707 0 0" />
      <geometry>
        <cylinder radius="${wheel_radius}" length='${wheel_length}' />
      </geometry>
      <material name="green">
        <color rgba="0.0 0.1 0 1.0"/>
      </material>
    </visual>
  </link>

  <!--camera-->
  <link name="camera">
    <collision>
      <origin xyz="0 0 0" rpy="0 0 0"/>
      <geometry>
        <box size="0.05 0.05 0.05" />
      </geometry>
    </collision>
    <visual>
      <origin xyz="0 0 0" rpy="0 0 0"/>
      <geometry>
        <box size="0.05 0.05 0.05" />
      </geometry>
      <material name="red">
        <color rgba="1.0 0 0 1.0"/>
      </material>
    </visual>
    <inertial>
      <mass value="0.1" />
      <origin xyz="0 0 0" rpy="0 0 0"/>
      <inertia ixx="1e-6" ixy="0" ixz="0" iyy="1e-6" iyz="0" izz="1e-6" />
    </inertial>
  </link>

  <!--hokuyo-->
  <link name="hokuyo">
    <collision>
      <origin xyz="0 0 0" rpy="0 0 0"/>
      <geometry>
        <box size="0.1 0.1 0.1" />
      </geometry>
    </collision>
    <visual>
      <origin xyz="0 0 0" rpy="0 0 0"/>
      <geometry>
        <mesh filename="package://my_robot/meshes/hokuyo.dae" />
      </geometry>
      <!-- <material name="red">
        <color rgba="1.0 0 0 1.0"/>
      </material> -->
    </visual>
    <inertial> 
      <mass value="1e-5" />
      <origin xyz="0 0 0" rpy="0 0 0"/>
      <inertia ixx="1e-6" ixy="0" ixz="0" iyy="1e-6" iyz="0" izz="1e-6" />
    </inertial>
  </link>

  <!-- Joints -->
  <joint name="robot_footprint_joint" type="fixed">
    <origin xyz="0 0 0" rpy="0 0 0" />
    <parent link="robot_footprint" />
    <child link="chassis" />
  </joint>

  <joint type="continuous" name="left_wheel_hinge">
    <origin xyz="0 0.15 0" rpy="0 0 0" />
    <parent link="chassis" />
    <child link="left_wheel" />
    <axis xyz="0 1 0" rpy="0 0 0" />
    <limit effort="10000" velocity="1000" />
    <dynamics damping="1.0" friction="1.0" />
  </joint>

  <joint type="continuous" name="right_wheel_hinge">
    <origin xyz="0 -0.15 0" rpy="0 0 0" />
    <parent link="chassis" />
    <child link="right_wheel" />
    <axis xyz="0 1 0" rpy="0 0 0" />
    <limit effort="10000" velocity="1000" />
    <dynamics damping="1.0" friction="1.0" />
  </joint>

  <joint name="camera_joint" type="fixed">
    <axis xyz="0 1 0" />
    <origin xyz="0.2 0 0" rpy="0 0 0"/>
    <parent link="chassis"/>
    <child link="camera"/>
  </joint>

  <joint name="hokuyo_joint" type="fixed">
    <axis xyz="0 1 0" />
    <origin xyz="0.15 0 0.1" rpy="0 0 0"/>
    <parent link="chassis"/>
    <child link="hokuyo"/>
  </joint>
</robot>